Workbook

Sheet Ekwipunek
B2: LVL | D2: Pozostałe do rozdania statystyki | G2: Pieniążki | L2: Życie w Walce | R2: Redukcja Fizycznych Obrażeń | V2: Rodzaje leczenia i koszt
B3: 1 | D3: =3+(B3-1)*2-SUM(D8:D11) -> 3 | G3: Miedziane | H3: Srebrne | I3: Złote | J3: Waga monet | L3: Bazowe | N3: Obrażenia | P3: Aktualne | V3: Nazwa | X3: Postaci | Z3: Zbroii/Tarczy
G4: 0 | H4: 200 | I4: 0 | J4: =I4*0.005+H4*0.004+G4*0.01 -> 0.8 | X4: Koszt | Y4: Leczy (hp) | Z4: Koszt | AA4: Leczy
L5: Postaci | M5: Zbroii | N5: Fizyczne | O5: Magiczne | P5: Postaci | Q5: Zbroii | R5: =C32*2+C33*4+C34*6+C27 -> 0 | V5: Leczenie dzienne | X5: 1 sen | Y5: =E22 -> 0
B6: Statystyki | G6: Miejsce Podręczne (wyekwipowanie przedmiotu - 0 akcji) | L6: =E13-E40 -> 10 | M6: =E40 -> 0 | N6: 0 | O6: 0 | P6: =L6-O6+IF(Q6=0,M6-N6,0) -> 10 | Q6: =IF(M6-N6>0,M6-N6,0) -> 0 | V6: Leki | X6: 1 lek (20s) | Y6: =(E13-E40)/2 -> 5
B7: Statystyki | C7: Modyfikatory postaci | D7: Wartości rozdane | E7: Użytkowe Statystyki | G7: Przedmiot (max 6) | H7: Rodzaj/Ilość | I7: Miejsce za Przedmiot | J7: Miejsce zużywane | V7: Leczenie opatrunek | X7: 1 opat (4s) | Y7: d4+wie
B8: Siła | D8: 0 | E8: =D8+C8 -> 0 | G8: Broń 1 | H8: Ręce | I8: =_xlfn.XLOOKUP(H8,'Zajmowane miejsce'!E3:E31,'Zajmowane miejsce'!F3:F31) -> 0 | J8: =I8 -> 0 | V8: Naprawa u kowala | Z8: 1 s | AA8: 1
B9: Zwinność | D9: 0 | E9: =D9+C9 -> 0 | G9: Broń 2 | H9: Ręce | I9: =_xlfn.XLOOKUP(H9,'Zajmowane miejsce'!E3:E31,'Zajmowane miejsce'!F3:F31) -> 0 | J9: =I9 -> 0 | V9: Narzędzia do zbroii lekkie | Z9: 12,5 s | AA9: 10
B10: Wiedza | D10: 0 | E10: =D10+C10 -> 0 | J10: =I10*H10 -> 0 | V10: Narzędzia do zbroii ciężkie | Z10: 12,5 s | AA10: 10
B11: Charyzma | D11: 0 | E11: =D11+C11 -> 0 | J11: =I11*H11 -> 0 | V11: Naprawa tarczy u kowala | Z11: 5s | AA11: Naprawa
B12: Parametry | C12: Podstawa | D12: Przyrost: lvl, statystyki | E12: Użytkowe parametry | J12: =I12*H12 -> 0 | V12: Narzędzia do naprawy tarcz | Z12: 20 s | AA12: Naprawia
B13: Max Życie | C13: 10 | D13: =(B3-1)*2+D8*3 -> 0 | E13: =D13+C13+E40 -> 10 | J13: =I13*H13 -> 0
B14: Obrona | C14: 10 | D14: =(B3-1)*0.8+D9 -> 0 | E14: =D14+C14+E41+C25 -> 10 | G14: Miejsce Podręczne | L14: Akcje
B15: Akcje | C15: 1 | D15: =(B3*0.5-0.5)+D9*0.5 -> 0 | E15: =D15+C15+E42+D25*0.5 -> 1 | G15: Modyfikator | H15: Dodawane miejsce | I15: Miejsce zużyte | J15: Pozostałe miejsce | L15: Na turę | M15: Zużyte | N15: Pozostałe
B16: Wytrwałość | C16: 1 | D16: =(B3-1)*0.25+D11*0.25 -> 0 | E16: =ROUND(D16+C16+E43+E25*0.5,0) -> 1 | G16: Baza | H16: 20 | I16: =SUM(J8:J13) -> 0 | J16: =H20-I16 -> 20 | L16: =E15 -> 1 | M16: =SUM(Obl!W3:W24) -> 0 | N16: =L16-M16 -> 1
B17: Ruch (ft) | C17: 30 | D17: 0 | E17: =C17+D17+E44+B27*5 -> 30 | G17: Ubrania z kieszeniami | H17: =IF(C43=FALSE,0,10) -> 0
G18: Pasek z mocowaniem | H18: =IF(C44=FALSE,0,10) -> 0
B19: Magia | G19: Siła | H19: =E8*2 -> 0 | L19: Karty Broń 1
B20: Punkty | D20: Zużyte | E20: Pozostałe | G20: Suma: | H20: =SUM(H16:H19) -> 20 | L20: =IF($E$16>=1,Obl!Z2,"") -> Karta 1 | N20: =IF($E$16>=1,Obl!AB2,"") -> Użyta | O20: FALSE | P20: =IF($E$16>=2,Obl!AD2,"") | R20: =IF($E$16>=2,Obl!AF2,"") | S20: FALSE | T20: =IF($E$16>=3,Obl!AH2,"") | V20: =IF($E$16>=3,Obl!AJ2,"") | W20: FALSE | X20: =IF($E$16>=4,Obl!AL2,"") | Z20: =IF($E$16>=4,Obl!AN2,"") | AA20: FALSE
B21: Mana na turę | C21: =ROUND(E8/3+E9*2/3,0) -> 0 | D21: =SUM(B25:E25)+SUM(B27:E27) -> 0 | E21: =C21-D21 -> 0 | L21: =IF($E$16>=1,Obl!Z3,"") -> Wyrzucona kostka | P21: =IF($E$16>=2,Obl!AD3,"") | R21: 7 | T21: =IF($E$16>=3,Obl!AH3,"") | X21: =IF($E$16>=4,Obl!AL3,"")
B22: Mana na dzień | C22: =ROUND((E10*2/3+E11/3)*3,0) -> 0 | D22: 0 | E22: =C22-D22 -> 0 | G22: Miejsce Niepodręczne (wyekwipowanie przedmiotu - 2 akcje) | L22: =IF($E$16>=1,Obl!Z4,"") -> Prosty | P22: =IF($E$16>=2,Obl!AD4,"") | T22: =IF($E$16>=3,Obl!AH4,"") | X22: =IF($E$16>=3,Obl!AL4,"")
B23: Mana na parametry (na 1 tura) | G23: Przedmiot (max 20) | H23: Ilość | I23: Miejsce za Przedmiot | J23: Miejsce zużywane | L23: =IF($E$16>=1,Obl!Z6,"") -> Zwykły, chamski atak | P23: =IF($E$16>=2,Obl!AD6,"") | T23: =IF($E$16>=3,Obl!AH6,"") | X23: =IF($E$16>=4,Obl!AL6,"")
B24: Życie (leczenie) | C24: Obrona | D24: Akcje | E24: Wytrwałość | J24: =I24*H24 -> 0
J25: =I25*H25 -> 0
B26: Ruch | C26: Redukcja obrażeń | D26: Przerzucenie kostki | E26: Inne | J26: =I26*H26 -> 0
J27: =I27*H27 -> 0 | L27: =IF($E$16>=1,Obl!Z10,"") -> Dmg | M27: =IF($E$16>=1,Obl!AA10,"") -> str | N27: =IF($E$16>=1,Obl!AB10,"") -> Akcja | O27: =IF($E$16>=1,Obl!AC10,"") -> 0.5 | P27: =IF($E$16>=2,Obl!AD10,"") | Q27: =IF($E$16>=2,Obl!AE10,"") | R27: =IF($E$16>=2,Obl!AF10,"") | S27: =IF($E$16>=2,Obl!AG10,"") | T27: =IF($E$16>=3,Obl!AH10,"") | U27: =IF($E$16>=3,Obl!AI10,"") | V27: =IF($E$16>=3,Obl!AJ10,"") | W27: =IF($E$16>=3,Obl!AK10,"") | X27: =IF($E$16>=4,Obl!AL10,"") | Y27: =IF($E$16>=4,Obl!AM10,"") | Z27: =IF($E$16>=4,Obl!AN10,"") | AA27: =IF($E$16>=4,Obl!AO10,"")
J28: =I28*H28 -> 0 | L28: =IF($E$16>=1,Obl!Z11,"") -> Trafienie | M28: =IF($E$16>=1,Obl!AA11,"") -> d20+dex | N28: =IF($E$16>=1,Obl!AB11,"") -> Ilośc celów | O28: =IF($E$16>=1,Obl!AC11,"") -> 1 | P28: =IF($E$16>=2,Obl!AD11,"") | Q28: =IF($E$16>=2,Obl!AE11,"") | R28: =IF($E$16>=2,Obl!AF11,"") | S28: =IF($E$16>=2,Obl!AG11,"") | T28: =IF($E$16>=3,Obl!AH11,"") | U28: =IF($E$16>=3,Obl!AI11,"") | V28: =IF($E$16>=3,Obl!AJ11,"") | W28: =IF($E$16>=3,Obl!AK11,"") | X28: =IF($E$16>=4,Obl!AL11,"") | Y28: =IF($E$16>=4,Obl!AM11,"") | Z28: =IF($E$16>=4,Obl!AN11,"") | AA28: =IF($E$16>=4,Obl!AO11,"")
B29: Zbroja | J29: =I29*H29 -> 0 | L29: =IF($E$16>=1,Obl!Z12,"") -> Zasięg | M29: =IF($E$16>=1,Obl!AA12,"") -> Mele | N29: =IF($E$16>=1,Obl!AB12,"") -> Tura | O29: =IF($E$16>=1,Obl!AC12,"") -> Gracza | P29: =IF($E$16>=2,Obl!AD12,"") | Q29: =IF($E$16>=2,Obl!AE12,"") | R29: =IF($E$16>=2,Obl!AF12,"") | S29: =IF($E$16>=2,Obl!AG12,"") | T29: =IF($E$16>=3,Obl!AH12,"") | U29: =IF($E$16>=3,Obl!AI12,"") | V29: =IF($E$16>=3,Obl!AJ12,"") | W29: =IF($E$16>=3,Obl!AK12,"") | X29: =IF($E$16>=4,Obl!AL12,"") | Y29: =IF($E$16>=4,Obl!AM12,"") | Z29: =IF($E$16>=4,Obl!AN12,"") | AA29: =IF($E$16>=4,Obl!AO12,"")
B30: Rodzaj | C30: Ilość | D30: Miejsce na fragment | E30: Miejsce zużywane | J30: =I30*H30 -> 0
B31: Skórzana | C31: 0 | D31: 8 | E31: =D31*C31 -> 0 | J31: =I31*H31 -> 0 | L31: Karty Broń 2
B32: Półpłytowa | C32: 0 | D32: 6 | E32: =D32*C32 -> 0 | J32: =I32*H32 -> 0 | L32: =IF($E$16>=1,Obl!Z15,"") -> Karta 1 | N32: =IF($E$16>=1,Obl!AB15,"") -> Użyta | O32: FALSE | P32: =IF($E$16>=2,Obl!AD15,"") | R32: =IF($E$16>=2,Obl!AF15,"") | S32: FALSE | T32: =IF($E$16>=3,Obl!AH15,"") | V32: =IF($E$16>=3,Obl!AJ15,"") | W32: FALSE | X32: =IF($E$16>=4,Obl!AL15,"") | Z32: =IF($E$16>=4,Obl!AN15,"") | AA32: FALSE
B33: Płytowa | C33: 0 | D33: 4 | E33: =D33*C33 -> 0 | J33: =I33*H33 -> 0 | L33: =IF($E$16>=1,Obl!Z16,"") -> Wyrzucona kostka | P33: =IF($E$16>=2,Obl!AD16,"") | T33: =IF($E$16>=3,Obl!AH16,"") | X33: =IF($E$16>=4,Obl!AL16,"")
B34: Stalowa | C34: 0 | D34: 4 | E34: =D34*C34 -> 0 | J34: =I34*H34 -> 0 | L34: =IF($E$16>=1,Obl!Z17,"") -> Prosty | P34: =IF($E$16>=2,Obl!AD17,"") | T34: =IF($E$16>=3,Obl!AH17,"") | X34: =IF($E$16>=4,Obl!AL17,"")
B35: Pozostałe miejsce | J35: =I35*H35 -> 0 | L35: =IF($E$16>=1,Obl!Z18,"") -> Zwykły, chamski atak | P35: =IF($E$16>=2,Obl!AD18,"") | T35: =IF($E$16>=3,Obl!AH18,"") | X35: =IF($E$16>=4,Obl!AL18,"")
B36: Max miejsce | C36: Zużywane miejsce | D36: Pozostałe miesjce zbroii | J36: =I36*H36 -> 0
B37: 24 | C37: =SUM(E31:E34) -> 0 | D37: =B37-C37 -> 24 | J37: =I37*H37 -> 0
J38: =I38*H38 -> 0
B39: Posiadasz | D39: Modyfikacje statystyk przez zbroję | J39: =I39*H39 -> 0 | L39: =IF($E$16>=1,Obl!Z22,"") -> Dmg | M39: =IF($E$16>=1,Obl!AA22,"") -> str | N39: =IF($E$16>=1,Obl!AB22,"") -> Akcja | O39: =IF($E$16>=1,Obl!AC22,"") -> 0.5 | P39: =IF($E$16>=2,Obl!AD22,"") | Q39: =IF($E$16>=2,Obl!AE22,"") | R39: =IF($E$16>=2,Obl!AF22,"") | S39: =IF($E$16>=2,Obl!AG22,"") | T39: =IF($E$16>=3,Obl!AH22,"") | U39: =IF($E$16>=3,Obl!AI22,"") | V39: =IF($E$16>=3,Obl!AJ22,"") | W39: =IF($E$16>=3,Obl!AK22,"") | X39: =IF($E$16>=4,Obl!AL22,"") | Y39: =IF($E$16>=4,Obl!AM22,"") | Z39: =IF($E$16>=4,Obl!AN22,"") | AA39: =IF($E$16>=4,Obl!AO22,"")
B40: Plecak | C40: FALSE | D40: Max życie | E40: {=SUM(C31:C34*5)} -> 0 | J40: =I40*H40 -> 0 | L40: =IF($E$16>=1,Obl!Z23,"") -> Trafienie | M40: =IF($E$16>=1,Obl!AA23,"") -> d20+dex | N40: =IF($E$16>=1,Obl!AB23,"") -> Ilośc celów | O40: =IF($E$16>=1,Obl!AC23,"") -> 1 | P40: =IF($E$16>=2,Obl!AD23,"") | Q40: =IF($E$16>=2,Obl!AE23,"") | R40: =IF($E$16>=2,Obl!AF23,"") | S40: =IF($E$16>=2,Obl!AG23,"") | T40: =IF($E$16>=3,Obl!AH23,"") | U40: =IF($E$16>=3,Obl!AI23,"") | V40: =IF($E$16>=3,Obl!AJ23,"") | W40: =IF($E$16>=3,Obl!AK23,"") | X40: =IF($E$16>=4,Obl!AL23,"") | Y40: =IF($E$16>=4,Obl!AM23,"") | Z40: =IF($E$16>=4,Obl!AN23,"") | AA40: =IF($E$16>=4,Obl!AO23,"")
B41: Plecak podróżnika | C41: FALSE | D41: Obrona | E41: =(C32*-0.2+C33*-0.5+C34*-1)/(B3/2) -> 0 | J41: =I41*H41 -> 0 | L41: =IF($E$16>=1,Obl!Z24,"") -> Zasięg | M41: =IF($E$16>=1,Obl!AA24,"") -> Mele | N41: =IF($E$16>=1,Obl!AB24,"") -> Tura | O41: =IF($E$16>=1,Obl!AC24,"") -> Gracza | P41: =IF($E$16>=2,Obl!AD24,"") | Q41: =IF($E$16>=2,Obl!AE24,"") | R41: =IF($E$16>=2,Obl!AF24,"") | S41: =IF($E$16>=2,Obl!AG24,"") | T41: =IF($E$16>=3,Obl!AH24,"") | U41: =IF($E$16>=3,Obl!AI24,"") | V41: =IF($E$16>=3,Obl!AJ24,"") | W41: =IF($E$16>=3,Obl!AK24,"") | X41: =IF($E$16>=4,Obl!AL24,"") | Y41: =IF($E$16>=4,Obl!AM24,"") | Z41: =IF($E$16>=4,Obl!AN24,"") | AA41: =IF($E$16>=4,Obl!AO24,"")
...

Sheet Broń biała
C2: Wartość dla karty | D2: Nazwa | E2: Akcje | F2: Zasięg | G2: Trafienie | H2: Dmg | I2: Ilość celów | J2: Wykonanie w turze | K2: Opis | L2: Koszt w srebrnych monetach
B3: Ręce | C3: 0 | D3: Prosty | E3: 0.5 | F3: Mele | G3: d20+dex | H3: str | I3: 1 | J3: Gracza | K3: Zwykły, chamski atak
C4: 3 | D4: Sierpowy | E4: 0.5 | F4: Mele | G4: d20+dex | H4: str+dex | I4: 1 | J4: Gracza | K4: Twój dex wlicza się do wyrzuconej kostki na trafienie (np. 17+3dex = kryt)
C5: 8 | D5: Kontra | E5: 0.5 | F5: Mele | G5: zawsze | H5: str | I5: 1 | J5: Wroga | K5: Zniwecz jedną akcję przeciwnika (skierowaną przeciw tobie)
C6: 10 | D6: Łokieto | E6: 1 | F6: Mele | G6: d20+dex | H6: str | I6: 1 | J6: Gracza/Soj | K6: Odepchnij wroga 5ft w wybranym kierunku (save: d20+str>13+str) || Advantage na kolejny atak w cel tego ataku
B7: Topór | C7: 0 | D7: Cios | E7: 1 | F7: Mele | G7: d20+dex | H7: d6+str | I7: 1 | J7: Gracza | K7: Niszczysz drewnianą tarczę wroga || Dezaktywujesz do końca tury inne tarcze | L7: 6
C8: 5 | D8: Ogłuszacz | E8: 1 | F8: Mele | G8: d20+dex | H8: d8+str | I8: 1 | J8: Gracza/Wroga | K8: Wróg twojego rozmiaru traci cały ruch || Cel tego ataku otrzymuje -4 do rzutów wszystkimi kostkami (save: d20+str>13+str)
C9: 10 | D9: Rąbanie | E9: 1.5 | F9: Mele | G9: d12+2xdex | H9: d6+str | I9: 4 | J9: Gracza | K9: Otrzymujesz 10ft ruchu (tylko raz)
B10: Miecz | C10: 0 | D10: Cięcie | E10: 1 | F10: Mele | G10: d20+dex | H10: d6+1/2(dex+str) | I10: 1 | J10: Gracza/Soj | K10: Zwykły atak | L10: 15
C11: 2 | D11: Blok | E11: 0.5 | F11: Mele | G11: X | H11: X | I11: 1 | J11: Wroga | K11: Zniwecz jedną akcję sonsiadującego przeciwnika (save: d20+dex>rzut na trafienie wroga)
C12: 5 | D12: Cios w plecy | E12: 0 | F12: Mele | G12: d20+dex | H12: d6+1/2(dex+str) | I12: 1 | J12: Sojusznika | K12: Zaatakuj sonsiadującego przeciwnika, po atakau sojusznika
C13: 7 | D13: Pchnięcie | E13: 1 | F13: 5ft | G13: d20+2xdex | H13: d8+1/2(dex+str) | I13: 1 | J13: Gracza/Soj | K13: Doskakujesz 5ft a następnie wykonujesz atak
C14: 10 | D14: Rozbrojenie | E14: 1 | F14: Mele | G14: X | H14: X | I14: 1 | J14: Sojusznka/Wro | K14: Zniwecz jedną akcje przeciniwka || Rozbrój wroga (save: d20+dex>d20+dex wroga)
B15: Buzdygan | C15: 0 | D15: Cios | E15: 1 | F15: Mele | G15: d20-2+dex | H15: 2xstr | I15: 1 | J15: Gracza | K15: Advantage na kolejny atak przeciwko trafionemu przeciwnikowi o mniejszym str od ciebie | L15: 5
C16: 5 | D16: Obuch | E16: 1 | F16: Mele | G16: d20-4+dex | H16: 3xstr | I16: 1 | J16: Gracza | K16: Odbierz turę przeciwnikowi o str mniejszym od ciebie
C17: 10 | D17: Łamacz | E17: 1 | F17: Mele | G17: d20-6+dex | H17: 4xstr | I17: 1 | J17: Gracza | K17: Advantage na wszystkie ataki przeciwko trafionemu przeciwnikowi o mniejszym str od ciebie || Jeżeli nie trafisz, przeciwnik zostaje trafiony "Ciosem"
B18: Włócznia | C18: 0 | D18: Pchnięcia | E18: 2 | F18: 5ft | G18: d20+dex | H18: d4+str | I18: 3 | J18: Gracza/Wroga | K18: W trakcie swojej tury możesz wykonac tylko jeden atak || Możesz wykonać tylko jeden atak na przeciwnika pozostajacego w twojej strefie kontrolii || Odpychasz wroga o 5ft (d20+str>13+str) | L18: 5
C19: 5 | D19: Ściana włóczni | E19: 1 | F19: 5ft | G19: d20+dex | H19: d4+str | I19: 3 | J19: Sojusznika | K19: Aktywój "Pchnięcia" po tym jak twój sojusznik aktywóje "Pchnięcia"
C20: 10 | D20: Przygotowanie | E20: 0 | J20: Gracza | K20: Wszystkie pchnięcia do końca następnej tury zadają d4+2xstr
B21: Miecz długi | C21: 0 | D21: Cięcie | E21: 1 | F21: Mele | G21: d20+dex | H21: d6+dex+str | I21: 1 | J21: Gracza | K21: Nie możesz używać innej broni jednoręcznej||zadaje 50% dmg potworą (jeśli rzut ponirzej 16) | L21: 25
C22: 5 | D22: Kontry | E22: 1 | F22: Mele | J22: Wroga | K22: Gdy przeciwnik nie trafi ataku wymierzonego w ciebie lub gdy zablokujesz atak przeciwnika, użyj "Cięcia" na przeciwniku
C23: 10 | D23: Ścięcie | E23: 1 | F23: Mele | G23: d20+dex | H23: 2d6+dex+str | I23: 1 | J23: Gracza | K23: Rzuć d4, w przypadku, gdy wyrzucisz 4, zabij przeciwnika swojego rozmiaru lub zadaj 3xdmg przeciwnikowi większemu od siebie
B25: Topór dwuręczny | C25: 0 | D25: Ścięcie | E25: 2 | F25: Mele | G25: d20+dex | H25: d12+2xstr | I25: 1 | J25: Gracza | K25: Jeżeli po tym gdy zadasz obrażenia przeciwnikowi, gdy zostanie mu mniej niż 8 życia, ten zostaje zabity || Niszczysz drewnianą tarczę wroga || Dezaktywujesz do końca tury inne tarcz | L25: 45
C26: 5 | D26: Siekacz | E26: 3 | F26: Mele | G26: d12+2xdex | H26: d6+2str | I26: sąsiedzi | J26: Gracza | K26: Jeżeli po tym gdy zadasz obrażenia przeciwnikowi, gdy zostanie mu mniej niż 6 życia, ten zostanie zabity
C27: 10 | D27: Gilotyna | E27: 2 | F27: 5ft | G27: d20+dex | H27: d12+2xstr | I27: 1 | J27: Gracza | K27: Ataku nie można zablokować || Jeżeli po tym gdy zadasz obrażenia przeciwnikowi, gdy zostanie mu mniej niż 20 życia, ten zostaje zabity
B28: Miecz dwuręczny | C28: 0 | D28: Pchnięcie | E28: 2 | F28: Mele | G28: d20+dex | H28: 2d6+(dex+str) | I28: 3 w rzędzie | J28: Gracza | K28: Potężny atak na wprost | L28: 60
C29: 1 | D29: Cięcie z zamachu | E29: 2 | F29: Mele/5ft | G29: d20+dex | H29: 2d6+(dex+str) | I29: 3 w łuku | J29: Gracza | K29: Potężny atak w łuku
C30: 2 | D30: Bloki | E30: 1 | F30: Mele/5ft | I30: 3 | J30: Wroga | K30: Zniwecz jedną akcję sonsiadującego przeciwnika (save: d20+2xdex>rzut na trafienie wroga) || Możliwe 3 użycia
C31: 10 | D31: Przygotowanie | E31: 1 | J31: Sojusznika/Wro | K31: Użyj dowolną kartę miecza dwóręcznego
B32: Młot dwuręczny | C32: 0 | D32: Uderzenie | E32: 2 | F32: 5ft | G32: d20+1/2dex | H32: d12+2xstr | I32: 1 | J32: Gracza | K32: Przeciwnik zostaje przesunięty na koniec turn ordera (save: d20+str>15+2xstr) | L32: 30
C33: 6 | D33: Trzęsienei ziemi | E33: 3 | F33: 5ft | G33: d20 | H33: d12+2xstr | I33: 1 | J33: Gracz | K33: Zniwecz akcję istot sonsiadujących z polem ataku (save: d20+str>15+2xstr) || Istoty na sonsiadujących polach otrzymuja d4+str dmg
C34: 10 | D34: Miażdżący cios | E34: 2 | F34: mele | G34: d20 | H34: 2d12+4xstr | I34: 1 | J34: Gracz | K34: Spraw, że sąsiedzi przeciwnika mogą go raz zaatakować za darmo (save: d20+str>15+2xstr)
B35: Włócznia długa | C35: 0 | D35: Pchnięcia | E35: 2 | F35: 10ft | G35: d20+dex | H35: d8+2xstr | I35: 3 | J35: Gracza/Wroga | K35: W trakcie swojej tury możesz wykonac tylko jeden atak || Możesz wykonać tylko jeden atak na przeciwnika pozostajacego w twojej strefie kontrolii || Odpychasz wroga o 5ft (d20+str>13+str) | L35: 20
C36: 5 | D36: Ściana włóczni | E36: 1 | F36: 10ft | G36: d20+dex | H36: d8+2xstr | I36: 3 | J36: Sojusznika | K36: Aktywój "Pchnięcia" po tym jak twój sojusznik aktywóje "Pchnięcia"
C37: 10 | D37: Przygotowanie | E37: 0 | J37: Gracza | K37: Wszystkie pchnięcia do końca następnej tury zadają d8+3xstr
B38: Morning star dwu. | C38: 0 | D38: Zamachy | E38: 1 | F38: 5ft | G38: d20+dex | H38: d8+1,5str | I38: 2 | J38: Gracza | K38: Odpycha 5ft || Możesz przerzucić 2 kostki w trakcie używania tej karty | L38: 25
C39: 3 | D39: Złapanie | E39: 1 | F39: 10ft | G39: d20+dex | H39: d6+str | I39: 1 | J39: Gracza | K39: Przewracasz i przeciągasz istotę 10ft w wybranym kierunku nie oddalając jej od siebie (save: d20+str>16+2str)
C40: 6 | D40: Szybkie uderzenia | E40: 1.5 | F40: 5ft | G40: d20+dex | H40: d8+1,5str | I40: 3 | J40: Gracza | K40: Możesz przerzucić 6 kostek w trakcie użwania tej karty
C41: 10 | D41: Złapanie | E41: 1.5 | F41: 5ft | G41: d20+dex | H41: d8+1,5str | I41: 6 | J41: Sojusznika | K41: Gdy sojusznik zaatakuje przeciwnika, możesz wykonać "Zamachy" || Sojusznik otrzymuje możliwość przerzucenia jednej ze swoich kostek w trakcie ataku
B42: Halabarda | C42: 0 | D42: Pchnięcie | E42: 2 | F42: 5ft | G42: d20+dex | H42: d4+2xstr | I42: 3 | J42: Gracza/Wroga | K42: W trakcie swojej tury możesz wykonac tylko jeden atak || Możesz wykonać tylko jeden atak na przeciwnika pozostajacego w twojej strefie kontrolii || Odpychasz wroga o 5ft (d20+str>13+2xstr) | L42: 75
...

Sheet Broń zasięgowa
C2: Wartość dla karty | D2: Nazwa | E2: Akcje | F2: Zasięg | G2: trafienie | H2: Dmg | I2: Ilość celów | J2: Wykonanie w turze | K2: Opis | L2: Koszt w srebrnych monetach
B3: Oszczep | C3: 0 | D3: Rzut/pchnięcie | E3: 1 | F3: 15/30/Mele | G3: d20+dex | H3: d8+str | I3: 1 | J3: Gracza | K3: Zmniejsza ruch wroga o 15ft, w następnej turze | L3: 5
C4: 5 | D4: Przebicie | E4: 1 | F4: 15/Mele | G4: d20+dex | H4: d8+str | I4: 2 w rzędzie | J4: Gracza | K4: Potężne pchnięcie lub rzut z bliska w przeciwnika
C5: 10 | D5: Szybki rzut | E5: 0 | F5: 15/30 | G5: d20+dex | H5: d8+str | I5: 1 | J5: Wroga | K5: Wykonaj atak gdy przeciwnik wejdzie w zasięg twojego rzutu || Zmniejsza ruch wroga o 15ft, w tej turze
B6: Toporek do rzucania | C6: 0 | D6: Rzut/zamach | E6: 0.75 | F6: 20/40/Mele | G6: d20+dex | H6: d4+1/2str | I6: 1 | J6: Gracza | K6: Zwykły atak toporkiem | L6: 4
C7: 5 | D7: Szybkie ataki | E7: 1.5 | F7: 20/40/Mele | G7: d20+dex | H7: d4+1/2str | I7: 2 | J7: Gracza | K7: Otrzymujesz dwie karty "Rzutu/zamachu"
C8: 10 | D8: Sieczka | E8: 1.5 | F8: Mele | G8: d20+2xdex | H8: d4+str | I8: 6 | J8: Gracza | K8: Wykonujesz ataki w wroga, do momentu w którym któryś z nich nie trafi lub gdy wykonasz ich 6
B9: Noże do rzucania | C9: 0 | D9: Rzut/Pchnięcie | E9: 0 | F9: 25/50/Mele | G9: d20+dex | H9: d4+1/2dex | I9: 1 | J9: Gracza | K9: Zwykły atak sztyletem | L9: 3
C10: 5 | D10: Szybkie ataki | E10: 1 | F10: 25/50/Mele | G10: d20+dex | H10: d4+1/2dex | I10: 3 | J10: Gracza | K10: Otrzymujesz 3 karty "Rzutu/Pchnięcia"
C11: 10 | D11: Nawałnica ostrzy | E11: 1.5 | F11: 25/50 | G11: d20+dex | H11: d4 | I11: X | J11: Gracza | K11: Możesz wykonać rzuty wszsytkimi wyjętymi przez ciebie nożami
B13: Kusza ręczna | C13: 0 | D13: Strzał | E13: 2 | F13: 40/200 | G13: d20+dex | H13: d10+4 | I13: 1 | J13: Gracza | K13: Zwykły strzał (1 bełt) | L13: 25
C14: 4 | D14: Strzał w brzuch | E14: 2 | F14: 40/200 | G14: d20+2xdex | H14: d10+4 | I14: 1 | J14: Gracza | K14: Przebij mu żołądek (1 bełt)
C15: 7 | D15: Strzał w stópki | E15: 2 | F15: 40/200 | G15: d20+dex | H15: d8+2 | I15: 1 | J15: Gracza | K15: Przeciwnik nie może się ruszyć w tej turze (1 bełt)
C16: 10 | D16: Strzał w głowę | E16: 2 | F16: 40/200 | G16: d20+1/2xdex | H16: 2d10+8 | I16: 1 | J16: Gracza | K16: Z tego się nie pozbiera (1 bełt)
B17: Kusza ciężka | C17: 0 | D17: Strzał | E17: 3 | F17: 80/400 | G17: d20+dex | H17: 2d10+8 | I17: 1 | J17: Gracza | K17: Zwykly strzał (1 bełt) | L17: 80
C18: 4 | D18: Przyczajenie | E18: 2 | F18: 80/400 | G18: d20+dex | H18: 2d10+8 | I18: 1 | J18: Wroga | K18: Gdy wróg pojawi się w twoim polu widzenie możesz wykonać "Strzał" (1 bełt)
C19: 8 | D19: Strzał przebijający | E19: 3 | F19: 80/400 | G19: d20+1/2dex | H19: 2d8+4 | I19: 2 w rzędzie | J19: Gracza | K19: Strzał ale nie tylko cel dostanie (1 bełt)
C20: 10 | D20: Strzał w głowę | E20: 3 | F20: 80/400 | G20: d20+dex | H20: 3d10+12 | I20: 1 | J20: Gracza | K20: Twój dex wlicza się do wyrzuconej kostki na trafienie (np. 17+3dex = kryt)
B21: bełt | L21: 1
B22: bełt ciężki | G22: -2 | H22: d4/d4+4 | L22: 6
B23: płonący bełt | G23: -2 | H23: d4/2xd4 | K23: adv na ataki w płonącego przeciwnika (save: d20+str<13) | L23: 4
B25: Łuk krótki | C25: 0 | D25: Strzał | E25: 1 | F25: 40/200 | G25: d20+dex | H25: d8+1/2str | I25: 1 | J25: Gracza | K25: po udanym trafieniu w przeciwnika możesz otrzymać adv na kolejne trafienia w tego przeciwnika lub adv na dmg na tego przeciwnika w tej turze (1 strzała) | L25: 65
C26: 7 | D26: Szybkie strzały | E26: 1.5 | F26: 30/200 | G26: d20+1/2dex | H26: d6+1/2str | I26: 3 | J26: Gracza | K26: po udanym trafieniu w przeciwnika możesz otrzymać adv na kolejne trafienia w tego przeciwnika lub adv na dmg na tego przeciwnika w tej turze (3 strzału)
C27: 10 | D27: Deszcz strzał | E27: 2 | F27: 120 | H27: d4+1/2str | I27: 5 pól | J27: Gracza | K27: Istoty na wybranych pięciu sonsiadujących plach jeżeli nie uda im się save throw, otrzymują obrażenia krytyczne (save: d20+dex>14+dex) (8 strzał)
B28: Łuk długi | C28: 0 | D28: Strzał | E28: 2 | F28: 60/400 | G28: d20+dex | H28: d8+str | I28: 1 | J28: Gracza | K28: Twój dex wlicza się do wyrzuconej kostki na trafienie (np. 17+3dex = kryt) (1 strzała) | L28: 100
C29: 5 | D29: Celny strzał | E29: 2 | F29: 80/400 | G29: d20+d4+2dex | H29: d8+1,5str | I29: 1 | J29: Gracza | K29: Twój dex wlicza się do wyrzuconej kostki na trafienie (np. 17+3dex = kryt) (1 strzała)
C30: 10 | D30: Strzał w oko | E30: 2 | F30: 120/400 | G30: 2d20+2d8+2dex | H30: d8+2str | I30: 1 | J30: Gracza | K30: Twój dex wlicza się do wyrzuconej kostki na trafienie (np. 17+3dex = kryt) || Jeżeli twój wynik na trafienie będzie większy niż 40, zadaj 4x obrażenia (1 strzała)
B31: strzała | L31: 1
B32: strzała giętka | G32: -1 | H32: d4/d4+str | K32: ruch wroga zmniejszony zostaje o 10ft | L32: 3
B33: płonąca strzała | G33: -2 | H33: d4/2xd4 | K33: adv na ataki w płonącego przeciwnika (save: d20+str<13) | L33: 4
B35: Samopał | C35: 0 | D35: Strzał | E35: 1 | F35: 30/50 | G35: d12+d4+dex | H35: 3d6+6 | I35: 1 | J35: Gracza | K35: Zwykły strzał (1 kula) | L35: 150
C36: 5 | D36: Kartacz | E36: 1 | F36: 15 | H36: 2d6+3 | I36: 3 w łuku | J36: Gracza | K36: Istoty otrzymują obrażenia, jeżeli nie uda im się save throw (save: d20+str>16) (1 kula)
C37: 10 | D37: Strzał w łeb | E37: 1 | F37: Mele | G37: d20+4dex | H37: 3d6+6 | I37: 1 | J37: Gracza | K37: Jeżeli trafisz, obrażenia są podwajane (1 kula)
B38: Muszkiet | C38: 0 | D38: Strzał | E38: 2 | F38: 30/120 | G38: d12+d4+dex | H38: 8d6+12 | I38: 1 | J38: Gracza | K38: Zwykły strzał (1 kula) | L38: 300
C39: 10 | D39: Kulka w łeb | E39: 2 | F39: 60/120 | G39: 2d12+2xdex | H39: 10d6+12 | I39: 1 | J39: Gracza | K39: Zwykły strzał, ale celniejszy (1 kula)
B40: kula | L40: 5
B41: amunicja rozbijająca | G41: -2 | H41: d6+stała-->2d4+0,5stała | L41: 10
B42: amunicja przeciwpancerna | G42: 1 | H42: d6+stała-->d8+1,5stała | L42: 20

Sheet Tarcze
C2: Wartość dla karty | D2: Nazwa | E2: Akcje | F2: Zasięg | G2: trafienie | H2: Dmg | I2: Ilość celów | J2: Wykonanie w turze | K2: Opis | L2: Koszt w srebrnych monetach
B3: Tarcza okrągła (drewniana) | C3: 0 | D3: Blok/Pchnięcie | E3: 1 | F3: Mele | G3: d20+dex | H3: d6+str | I3: 1 | J3: Gracza/Wroga | K3: Możesz dokonać ataku lub zablokować jeden atak wroga (d20+4<dmg wroga --> tarcza zostaje niszczona) | L3: 5
C4: 5 | D4: Pozycja obronna | E4: 1 | J4: Gracza/Soj | K4: Możesz zablokować 2 ataki wroga (d20+4<dmg wroga --> tarcza zostaje niszczona)
C5: 10 | D5: Szarża | E5: 1 | F5: Mele | G5: d20+dex | H5: d6+2xstr | I5: 1 | J5: Gracza | K5: Otrzymuejsz 15ft ruchu (raz na turę) || Przeciwnik w którego uderzysz zostaje wyrzucony na koniec turn ordera
B6: Tarcza migdałowata (drewniana) | C6: 0 | D6: Blok/Pchnięcie | E6: 1 | F6: Mele | G6: d20+dex | H6: d4+str | I6: 1 | J6: Gracza/Wroga | K6: Możesz dokonać ataku lub zablokować jeden atak wroga (d20+6<dmg wroga --> tarcza zostaje niszczona) | L6: 5
C7: 5 | D7: Pozycja obronna | E7: 1 | J7: Gracza/Soj | K7: Możesz zablokować 2 ataki wroga wymierzone w ciebie lub sojusznika (d20+6<dmg wroga --> tarcza zostaje niszczona)
C8: 10 | D8: Szarża | E8: 1 | F8: Mele | G8: d20+dex | H8: d4+2xstr | I8: 1 | J8: Gracza | K8: Otrzymuejsz 15ft ruchu (raz na turę) || Przeciwnik w którego uderzysz zostaje wyrzucony na koniec turn ordera
B9: Puklerz (drewniany) | C9: 0 | D9: Blok/Cios | E9: 1 | F9: Mele | G9: d20+dex | H9: d4+2xstr | I9: 1 | J9: Gracza/Wroga | K9: Możesz dokonać ataku lub zablokować jeden atak wroga (d20+12<dmg wroga --> tarcza zostaje niszczona) | L9: 3
C10: 10 | D10: Mistrz uników | E10: 1 | J10: Gracza | K10: Do końca walki otrzymuejsz +2ac
B11: Tarcza rzymska (drewniana) | C11: 0 | D11: Blok/Cios | E11: 1 | F11: Mele | G11: d20+dex | H11: d4+1/2str | I11: 1 | J11: Gracza/Wroga | K11: Możesz dokonać ataku lub zablokować jeden atak wroga (d20+8<dmg wroga --> tarcza zostaje niszczona) | L11: 10
C12: 6 | D12: Drewniana ściana | E12: 1 | J12: Gracza/Soj | K12: Możesz zablokować 3 ataki wroga wymierzone w ciebie lub sojusznika (d20+8<dmg wroga --> tarcza zostaje niszczona)
C13: 10 | D13: Nieporuszalny obiekt | E13: 1 | J13: Gracza | K13: Możesz zablokować wszystke ataki wroga wymierzone w ciebie (d20+8<dmg wroga --> tarcza zostaje niszczona) || Wróg nie może wyjść z twojej strefy kontrolii
B14: Tarcza okrągła (żelana) | C14: 0 | D14: Blok/Pchnięcie | E14: 1 | F14: Mele | G14: d20+dex | H14: d6+str | I14: 1 | J14: Gracza/Wroga | K14: Możesz dokonać ataku lub zablokować jeden atak wroga (d20+8<dmg wroga --> tarcza zostaje niszczona) | L14: 50
C15: 5 | D15: Pozycja obronna | E15: 1 | J15: Gracza/Soj | K15: Możesz zablokować 2 ataki wroga (d20+8<dmg wroga --> tarcza zostaje niszczona)
C16: 10 | D16: Szarża | E16: 1 | F16: Mele | G16: d20+dex | H16: d6+2xstr | I16: 1 | J16: Gracza | K16: Otrzymuejsz 15ft ruchu (raz na turę) || Przeciwnik w którego uderzysz zostaje wyrzucony na koniec turn ordera
B17: Tarcza migdałowata (żelazna) | C17: 0 | D17: Blok/Pchnięcie | E17: 1 | F17: Mele | G17: d20+dex | H17: d4+str | I17: 1 | J17: Gracza/Wroga | K17: Możesz dokonać ataku lub zablokować jeden atak wroga (d20+12<dmg wroga --> tarcza zostaje niszczona) | L17: 50
C18: 5 | D18: Pozycja obronna | E18: 1 | J18: Gracza/Soj | K18: Możesz zablokować 2 ataki wroga (d20+12<dmg wroga --> tarcza zostaje niszczona)
C19: 10 | D19: Szarża | E19: 1 | F19: Mele | G19: d20+dex | H19: d4+2xstr | I19: 1 | J19: Gracza | K19: Otrzymuejsz 15ft ruchu (raz na turę) || Przeciwnik w którego uderzysz zostaje wyrzucony na koniec turn ordera
B20: Puklerz (żelazny) | C20: 0 | D20: Blok/Cios | E20: 1 | F20: Mele | G20: d20+dex | H20: d4+2xstr | I20: 1 | J20: Gracza/Wroga | K20: Możesz dokonać ataku lub zablokować jeden atak wroga (d20+16<dmg wroga --> tarcza zostaje niszczona) | L20: 30
C21: 10 | D21: Mistrz uników | E21: 1 | J21: Gracza | K21: Do końca walki otrzymuejsz +2ac
B22: Tarcza rzymska (żelazna) | C22: 0 | D22: Blok/Cios | E22: 1 | F22: Mele | G22: d20+dex | H22: d4+1/2str | I22: 1 | J22: Gracza/Wroga | K22: Możesz dokonać ataku lub zablokować jeden atak wroga (d20+12<dmg wroga --> tarcza zostaje niszczona) | L22: 100
C23: 5 | D23: Drewniana ściana | E23: 1 | J23: Gracza/Soj | K23: Możesz zablokować 3 ataki wroga wymierzone w ciebie lub sojusznika (d20+12<dmg wroga --> tarcza zostaje niszczona)
C24: 10 | D24: Nieporuszalny obiekt | E24: 1 | J24: Gracza | K24: Możesz zablokować wszystke ataki wroga wymierzone w ciebie (d20+12<dmg wroga --> tarcza zostaje niszczona) || Wróg nie może wyjść z twojej strefy kontrolii

Sheet Zbroje
C2: Koszt | D2: Życie | E2: Wpływ na parametry | F2: Maksymalna ilość zakupień | G2: Ilość redukowanych obrażeń
B3: zbroja skórzana | C3: 15 | D3: 5 | F3: 4
B4: zbroja półpłytowa | C4: 30 | D4: 5 | E4: Obrona -0,4 || Akcje -0,2 || Wytrwałość -0,125 || Ruch -1 | F4: 6 | G4: 2
B5: zbroja płytowa | C5: 50 | D5: 5 | E5: Obrona -1 || Akcje -0,4 || Wytrwałość -0,25 || Ruch -1,5 | F5: 8 | G5: 4
B6: zbroja płytowa (stalowa) | C6: X | D6: 5 | E6: Obrona -2 || Akcje -0,8 || Wytrwałość -0,25 || Ruch -2 | F6: 8 | G6: 6
B7: narzędzia lekkie zbroje | C7: 50 | D7: 1h | E7: naprawia 10 życia zbroii (posiada 4 użycia) | F7: użycia/10
B8: narzędzia ciężkie zbroje | C8: 100 | D8: 1h | E8: naprawia 10 życia zbroii (posiada 8 użyć) | F8: użycia/10

Sheet Różne
C2: Koszt (srebro) | D2: Używanie | E2: Działanie | F2: Zużywane miejsce z eq
B3: Zaopatrzenie | C3: 20 | D3: raz dziennie | E3: leczy max hp po krótkim odpoczynku | F3: 2/10
B4: Leki | C4: 4 | D4: 10min | E4: można go użyć raz po każdej walce, leczy d4 dmg za każde 10 życia postaci+wis (działa tylko na obrażenia zadane w walce po której zostanie użyte) | F4: 1/10
B5: Opatrunek | C5: 1 | E5: woda, jedzenie. Liny, pochodnie, (w razie potrzeby dopisać) (zużywasz 1 dziennie + na różne akcje) | F5: 1/10
B6: Mała mikstura | C6: ~30 | D6: 5 akcji | E6: różnie | F6: 2/10
B7: Średnia mikstrura | C7: ~100 | D7: 5 akcji | E7: różnie | F7: 2,5/10
B8: Duża mikstura | C8: ~400 | D8: 5 akcji | E8: różnie | F8: 3/10
B10: Ubrania chłopskie | C10: ~5 | E10: wyglądasz jak chłop || możesz nosić jeden zestaw bez kary do miesjca w eq | F10: 5/10
B11: Ubrania mieszczańskie | C11: ~50 | E11: wyglądasz jak mieszczanin || możesz nosić jeden zestaw bez kary do miesjca w eq | F11: 5/10
B12: Ubrania szlacheckie | C12: ~500 | E12: wyglądasz jak szlachcic || możesz nosić jeden zestaw bez kary do miesjca w eq | F12: 5/10
B14: Kołczan | C14: 4 | E14: może utrzymać do 20 strzał/bełtów || możecie nosić jeden przy sobie i jednen w eq nie używając miejsca | F14: 1 lub 5/10
B15: Plecak | C15: 10 | E15: dodaje 1 miesjce w ekwipuku || możesz nosić jeden bez kary do miesjca w eq | F15: 5 lub 10/10
B16: Plecak podróżnika | C16: 40 | E16: dodaje 2 miesjce w ekwipuku || możesz nosić jeden bez kary do miesjca w eq | F16: 7,5 lub 20/10
B17: Ubranie z kieszeniami | C17: koszt+20% | E17: dodają +1/2 miesjca w eq || miejsce staje się miejscem podręczym o ile nie nosisz zbroii || możesz nosić jeden zestaw bez kary do miesjca w eq | F17: 5/10
B18: Pasek z mocowaniem | C18: 4/20/100 | E18: dodają +1/2 miesjca podręcznego || możesz nosić jeden zestaw bez kary do miesjca w eq | F18: 2/10
B20: Narzędzia lekkie zbroje | C20: 50 | D20: 1h | E20: naprawia 10 życia zbroii (posiada 4 użycia) | F20: użycia/10
B21: Narzędzia ciężkie zbroje | C21: 100 | D21: 1h | E21: naprawia 15 życia zbroii (posiada 6 użyć) | F21: użycia/10
B22: Zaopatrzenie | C22: 1 | E22: woda, jedzenie. Liny, pochodnie, (w razie potrzeby dopisać) (zużywasz 1 dziennie + na różne akcje) | F22: 1/10
B24: Mały kamień magiczny | C24: ~10 | E24: posiada 8 miejsca | F24: 1/10
B25: Średni kamień magiczny | C25: ~100 | E25: posiada 32 miejsc | F25: 2/10
B26: Duży kamień magiczny | C26: ~1000 | E26: posiada 128 miejsc | F26: 3/10

Sheet Zajmowane miejsce
C2: Zużywane miejsce z eq | F2: Zużywane miejsce z eq | I2: Zużywane miejsce z eq
B3: Zaopatrzenie | C3: 1 | E3: Ręce | F3: 0 | H3: Narzędzia do naprawy tarcz | I3: 5*użycia/10
B4: Leki | C4: 2 | E4: Topór | F4: 10 | H4: Zestaw naprawczy tarcze | I4: 2,5*użyć/10
B5: Opatrunek | C5: 1 | E5: Miecz | F5: 7,5
B6: Woda święcona | C6: 2 | E6: Buzdygan | F6: 7,5 | H6: Narzędzia lekkie zbroje | I6: użycia/10
B7: Mała mikstura | C7: 2 | E7: Włócznia | F7: 10 | H7: Narzędzia ciężkie zbroje | I7: użycia/10
B8: Średnia mikstrura | C8: 2,5 | E8: Miecz długi | F8: 10
B9: Duża mikstura | C9: 3 | E9: Topór dwuręczny | F9: 20
E10: Miecz dwuręczny | F10: 20
B11: Ubrania chłopskie | C11: 5 | E11: Młot dwuręczny | F11: 20
B12: Ubrania mieszczańskie | C12: 5 | E12: Włócznia długa | F12: 20
B13: Ubrania szlacheckie | C13: 5 | E13: Morning star dwuręczny | F13: 20
E14: Halabarda | F14: 20
B15: Kołczan | C15: 1 lub 5/10 | E15: Kusza ręczna | F15: 7,5
B16: Plecak | C16: 5 lub 10/10 | E16: Kusza ciężka | F16: 20
B17: Plecak podróżnika | C17: 7,5 lub 20/10 | E17: Łuk krótki | F17: 7,5
B18: Ubranie z kieszeniami | C18: 5/10 | E18: Łuk długi | F18: 20
B19: Pasek z mocowaniem | C19: 2/10 | E19: Samopał | F19: 10
E20: Muszkiet | F20: 20
B21: Narzędzia lekkie zbroje | C21: użycia/10 | E21: Oszczep | F21: 5
B22: Narzędzia ciężkie zbroje | C22: użycia/10 | E22: Toporek do rzucania | F22: 3,3
B23: Zaopatrzenie | C23: 1/10 | E23: Noże do rzucania | F23: 2,5
E24: Tarcza okrągła (drewniana) | F24: 7,5
B25: Mały kamień magiczny | C25: 1/10 | E25: Tarcza migdałowata (drewniana) | F25: 10
B26: Średni kamień magiczny | C26: 2/10 | E26: Puklerz (drewniany) | F26: 5
B27: Duży kamień magiczny | C27: 3/10 | E27: Tarcza rzymska (drewniana) | F27: 10
E28: Tarcza okrągła (żelazna) | F28: 7,5
E29: Tarcza migdałowata (żelazna) | F29: 10
E30: Puklerz (żelazny) | F30: 5
E31: Tarcza rzymska (żelazna) | F31: 10

Sheet Obl
Q1: Broń 1 | Z1: Karty Broń 1
C2: Wartość dla karty | D2: ile | E2: Nazwa | F2: Akcje | G2: Zasięg | H2: Trafienie | I2: Dmg | J2: Ilość celów | K2: Wykonanie w turze | L2: Opis | M2: Koszt w srebrnych monetach | O2: Ręce | Q2: kostki | R2: liczba | U2: akcje | V2: czy użyta? | Z2: Karta 1 | AB2: Użyta | AC2: =Ekwipunek!O20 -> FALSE | AD2: Karta 2 | AF2: Użyta | AG2: =Ekwipunek!S20 -> FALSE | AH2: Karta 3 | AJ2: Użyta | AK2: =Ekwipunek!W20 -> FALSE | AL2: Karta 4 | AN2: Użyta | AO2: =Ekwipunek!AA20 -> FALSE
B3: Ręce | C3: 0 | D3: =COUNT(C3:C6) -> 4 | E3: Prosty | F3: 0.5 | G3: Mele | H3: d20+dex | I3: str | J3: 1 | K3: Gracza | L3: Zwykły, chamski atak | O3: Topór | Q3: {=OFFSET(_xlfn.XLOOKUP(Ekwipunek!H8,Obl!$B$3:$B$94,Obl!$C$3:$C$94),0,0,_xlfn.XLOOKUP(Ekwipunek!H8,Obl!$B$3:$B$94,$D$3:$D$94))} -> 0 | R3: 0 | T3: karta 1 | U3: =Ekwipunek!O27 -> 0.5 | V3: =Ekwipunek!O20 -> FALSE | W3: =IF(V3=TRUE,U3,0) -> 0 | Z3: Wyrzucona kostka | AB3: =Ekwipunek!N21 -> 0 | AD3: Wyrzucona kostka | AF3: =Ekwipunek!R21 -> 7 | AH3: Wyrzucona kostka | AJ3: =Ekwipunek!V21 -> 0 | AL3: Wyrzucona kostka | AN3: =Ekwipunek!Z21 -> 0
C4: 3 | E4: Sierpowy | F4: 0.5 | G4: Mele | H4: d20+dex | I4: str+dex | J4: 1 | K4: Gracza | L4: Twój dex wlicza się do wyrzuconej kostki na trafienie (np. 17+3dex = kryt) | O4: Miecz | Q4: 3 | R4: 1 | T4: karta 2 | U4: =Ekwipunek!S27 | V4: =Ekwipunek!S20 -> FALSE | W4: =IF(V4=TRUE,U4,0) -> 0 | Z4: {=INDEX($B$3:$M$94,MATCH(Ekwipunek!$H$8,Obl!$B$3:$B$94,0)+_xlfn.XLOOKUP(AB$3,Obl!$Q$3:$Q$10,Obl!$R$3:$R$10,,-1),4)} -> Prosty | AD4: {=INDEX($B$3:$M$94,MATCH(Ekwipunek!$H$8,Obl!$B$3:$B$94,0)+_xlfn.XLOOKUP(AF$3,Obl!$Q$3:$Q$10,Obl!$R$3:$R$10,,-1),4)} -> Sierpowy | AH4: {=INDEX($B$3:$M$94,MATCH(Ekwipunek!$H$8,Obl!$B$3:$B$94,0)+_xlfn.XLOOKUP(AJ$3,Obl!$Q$3:$Q$10,Obl!$R$3:$R$10,,-1),4)} -> Prosty | AL4: {=INDEX($B$3:$M$94,MATCH(Ekwipunek!$H$8,Obl!$B$3:$B$94,0)+_xlfn.XLOOKUP(AN$3,Obl!$Q$3:$Q$10,Obl!$R$3:$R$10,,-1),4)} -> Prosty
C5: 8 | E5: Kontra | F5: 0.5 | G5: Mele | H5: zawsze | I5: str | J5: 1 | K5: Wroga | L5: Zniwecz jedną akcję przeciwnika (skierowaną przeciw tobie) | O5: Buzdygan | Q5: 8 | R5: 2
C6: 10 | E6: Łokieto | F6: 1 | G6: Mele | H6: d20+dex | I6: str | J6: 1 | K6: Gracza/Soj | L6: Odepchnij wroga 5ft w wybranym kierunku (save: d20+str>13+str) || Advantage na kolejny atak w cel tego ataku | O6: Włócznia | Q6: 10 | R6: 3 | T6: karta 3 | U6: =Ekwipunek!W27 | V6: =Ekwipunek!W20 -> FALSE | W6: =IF(V6=TRUE,U6,0) -> 0 | Z6: {=INDEX($B$3:$M$94,MATCH(Ekwipunek!$H$8,Obl!$B$3:$B$94,0)+_xlfn.XLOOKUP(AB$3,Obl!$Q$3:$Q$10,Obl!$R$3:$R$10,,-1),11)} -> Zwykły, chamski atak | AD6: {=INDEX($B$3:$M$94,MATCH(Ekwipunek!$H$8,Obl!$B$3:$B$94,0)+_xlfn.XLOOKUP(AF$3,Obl!$Q$3:$Q$10,Obl!$R$3:$R$10,,-1),11)} -> Twój dex wlicza się do wyrzuconej kostki na trafienie (np. 17+3dex = kryt) | AH6: {=INDEX($B$3:$M$94,MATCH(Ekwipunek!$H$8,Obl!$B$3:$B$94,0)+_xlfn.XLOOKUP(AJ$3,Obl!$Q$3:$Q$10,Obl!$R$3:$R$10,,-1),11)} -> Zwykły, chamski atak | AL6: {=INDEX($B$3:$M$94,MATCH(Ekwipunek!$H$8,Obl!$B$3:$B$94,0)+_xlfn.XLOOKUP(AN$3,Obl!$Q$3:$Q$10,Obl!$R$3:$R$10,,-1),11)} -> Zwykły, chamski atak
B7: Topór | C7: 0 | D7: =COUNT(C7:C9) -> 3 | E7: Cios | F7: 1 | G7: Mele | H7: d20+dex | I7: d6+str | J7: 1 | K7: Gracza | L7: Niszczysz drewnianą tarczę wroga || Dezaktywujesz do końca tury inne tarcze | M7: 6 | O7: Miecz długi | R7: 4 | T7: karta 4 | U7: =Ekwipunek!AA27 | V7: =Ekwipunek!AA20 -> FALSE | W7: =IF(V7=TRUE,U7,0) -> 0
C8: 5 | E8: Ogłuszacz | F8: 1 | G8: Mele | H8: d20+dex | I8: d8+str | J8: 1 | K8: Gracza/Wroga | L8: Wróg twojego rozmiaru traci cały ruch || Cel tego ataku otrzymuje -4 do rzutów wszystkimi kostkami (save: d20+str>13+str) | O8: Topór dwuręczny | R8: 5
C9: 10 | E9: Rąbanie | F9: 1.5 | G9: Mele | H9: d12+2xdex | I9: d6+str | J9: 4 | K9: Gracza | L9: Otrzymujesz 10ft ruchu (tylko raz) | O9: Miecz dwuręczny | R9: 6
B10: Miecz | C10: 0 | D10: =COUNT(C10:C14) -> 5 | E10: Cięcie | F10: 1 | G10: Mele | H10: d20+dex | I10: d6+1/2(dex+str) | J10: 1 | K10: Gracza/Soj | L10: Zwykły atak | M10: 15 | O10: Młot dwuręczny | R10: 7 | Z10: Dmg | AA10: {=INDEX($B$3:$M$94,MATCH(Ekwipunek!$H$8,Obl!$B$3:$B$94,0)+_xlfn.XLOOKUP(AB$3,Obl!$Q$3:$Q$10,Obl!$R$3:$R$10,,-1),8)} -> str | AB10: Akcja | AC10: {=INDEX($B$3:$M$94,MATCH(Ekwipunek!$H$8,Obl!$B$3:$B$94,0)+_xlfn.XLOOKUP(AB$3,Obl!$Q$3:$Q$10,Obl!$R$3:$R$10,,-1),5)} -> 0.5 | AD10: Dmg | AE10: {=INDEX($B$3:$M$94,MATCH(Ekwipunek!$H$8,Obl!$B$3:$B$94,0)+_xlfn.XLOOKUP(AF$3,Obl!$Q$3:$Q$10,Obl!$R$3:$R$10,,-1),8)} -> str+dex | AF10: Akcja | AG10: {=INDEX($B$3:$M$94,MATCH(Ekwipunek!$H$8,Obl!$B$3:$B$94,0)+_xlfn.XLOOKUP(AF$3,Obl!$Q$3:$Q$10,Obl!$R$3:$R$10,,-1),5)} -> 0.5 | AH10: Dmg | AI10: {=INDEX($B$3:$M$94,MATCH(Ekwipunek!$H$8,Obl!$B$3:$B$94,0)+_xlfn.XLOOKUP(AJ$3,Obl!$Q$3:$Q$10,Obl!$R$3:$R$10,,-1),8)} -> str | AJ10: Akcja | AK10: {=INDEX($B$3:$M$94,MATCH(Ekwipunek!$H$8,Obl!$B$3:$B$94,0)+_xlfn.XLOOKUP(AJ$3,Obl!$Q$3:$Q$10,Obl!$R$3:$R$10,,-1),5)} -> 0.5 | AL10: Dmg | AM10: {=INDEX($B$3:$M$94,MATCH(Ekwipunek!$H$8,Obl!$B$3:$B$94,0)+_xlfn.XLOOKUP(AN$3,Obl!$Q$3:$Q$10,Obl!$R$3:$R$10,,-1),8)} -> str | AN10: Akcja | AO10: {=INDEX($B$3:$M$94,MATCH(Ekwipunek!$H$8,Obl!$B$3:$B$94,0)+_xlfn.XLOOKUP(AN$3,Obl!$Q$3:$Q$10,Obl!$R$3:$R$10,,-1),5)} -> 0.5
C11: 2 | E11: Blok | F11: 0.5 | G11: Mele | H11: X | I11: X | J11: 1 | K11: Wroga | L11: Zniwecz jedną akcję sonsiadującego przeciwnika (save: d20+dex>rzut na trafienie wroga) | O11: Włócznia długa | Z11: Trafienie | AA11: {=INDEX($B$3:$M$94,MATCH(Ekwipunek!$H$8,Obl!$B$3:$B$94,0)+_xlfn.XLOOKUP(AB$3,Obl!$Q$3:$Q$10,Obl!$R$3:$R$10,,-1),7)} -> d20+dex | AB11: Ilośc celów | AC11: {=INDEX($B$3:$M$94,MATCH(Ekwipunek!$H$8,Obl!$B$3:$B$94,0)+_xlfn.XLOOKUP(AB$3,Obl!$Q$3:$Q$10,Obl!$R$3:$R$10,,-1),9)} -> 1 | AD11: Trafienie | AE11: {=INDEX($B$3:$M$94,MATCH(Ekwipunek!$H$8,Obl!$B$3:$B$94,0)+_xlfn.XLOOKUP(AF$3,Obl!$Q$3:$Q$10,Obl!$R$3:$R$10,,-1),7)} -> d20+dex | AF11: Ilośc celów | AG11: {=INDEX($B$3:$M$94,MATCH(Ekwipunek!$H$8,Obl!$B$3:$B$94,0)+_xlfn.XLOOKUP(AF$3,Obl!$Q$3:$Q$10,Obl!$R$3:$R$10,,-1),9)} -> 1 | AH11: Trafienie | AI11: {=INDEX($B$3:$M$94,MATCH(Ekwipunek!$H$8,Obl!$B$3:$B$94,0)+_xlfn.XLOOKUP(AJ$3,Obl!$Q$3:$Q$10,Obl!$R$3:$R$10,,-1),7)} -> d20+dex | AJ11: Ilośc celów | AK11: {=INDEX($B$3:$M$94,MATCH(Ekwipunek!$H$8,Obl!$B$3:$B$94,0)+_xlfn.XLOOKUP(AJ$3,Obl!$Q$3:$Q$10,Obl!$R$3:$R$10,,-1),9)} -> 1 | AL11: Trafienie | AM11: {=INDEX($B$3:$M$94,MATCH(Ekwipunek!$H$8,Obl!$B$3:$B$94,0)+_xlfn.XLOOKUP(AN$3,Obl!$Q$3:$Q$10,Obl!$R$3:$R$10,,-1),7)} -> d20+dex | AN11: Ilośc celów | AO11: {=INDEX($B$3:$M$94,MATCH(Ekwipunek!$H$8,Obl!$B$3:$B$94,0)+_xlfn.XLOOKUP(AN$3,Obl!$Q$3:$Q$10,Obl!$R$3:$R$10,,-1),9)} -> 1
C12: 5 | E12: Cios w plecy | F12: 0 | G12: Mele | H12: d20+dex | I12: d6+1/2(dex+str) | J12: 1 | K12: Sojusznika | L12: Zaatakuj sonsiadującego przeciwnika, po atakau sojusznika | O12: Morning star dwuręczny | Z12: Zasięg | AA12: {=INDEX($B$3:$M$94,MATCH(Ekwipunek!$H$8,Obl!$B$3:$B$94,0)+_xlfn.XLOOKUP(AB$3,Obl!$Q$3:$Q$10,Obl!$R$3:$R$10,,-1),6)} -> Mele | AB12: Tura | AC12: {=INDEX($B$3:$M$94,MATCH(Ekwipunek!$H$8,Obl!$B$3:$B$94,0)+_xlfn.XLOOKUP(AB$3,Obl!$Q$3:$Q$10,Obl!$R$3:$R$10,,-1),10)} -> Gracza | AD12: Zasięg | AE12: {=INDEX($B$3:$M$94,MATCH(Ekwipunek!$H$8,Obl!$B$3:$B$94,0)+_xlfn.XLOOKUP(AF$3,Obl!$Q$3:$Q$10,Obl!$R$3:$R$10,,-1),6)} -> Mele | AF12: Tura | AG12: {=INDEX($B$3:$M$94,MATCH(Ekwipunek!$H$8,Obl!$B$3:$B$94,0)+_xlfn.XLOOKUP(AF$3,Obl!$Q$3:$Q$10,Obl!$R$3:$R$10,,-1),10)} -> Gracza | AH12: Zasięg | AI12: {=INDEX($B$3:$M$94,MATCH(Ekwipunek!$H$8,Obl!$B$3:$B$94,0)+_xlfn.XLOOKUP(AJ$3,Obl!$Q$3:$Q$10,Obl!$R$3:$R$10,,-1),6)} -> Mele | AJ12: Tura | AK12: {=INDEX($B$3:$M$94,MATCH(Ekwipunek!$H$8,Obl!$B$3:$B$94,0)+_xlfn.XLOOKUP(AJ$3,Obl!$Q$3:$Q$10,Obl!$R$3:$R$10,,-1),10)} -> Gracza | AL12: Zasięg | AM12: {=INDEX($B$3:$M$94,MATCH(Ekwipunek!$H$8,Obl!$B$3:$B$94,0)+_xlfn.XLOOKUP(AN$3,Obl!$Q$3:$Q$10,Obl!$R$3:$R$10,,-1),6)} -> Mele | AN12: Tura | AO12: {=INDEX($B$3:$M$94,MATCH(Ekwipunek!$H$8,Obl!$B$3:$B$94,0)+_xlfn.XLOOKUP(AN$3,Obl!$Q$3:$Q$10,Obl!$R$3:$R$10,,-1),10)} -> Gracza
C13: 7 | E13: Pchnięcie | F13: 1 | G13: 5ft | H13: d20+2xdex | I13: d8+1/2(dex+str) | J13: 1 | K13: Gracza/Soj | L13: Doskakujesz 5ft a następnie wykonujesz atak | O13: Halabarda
C14: 10 | E14: Rozbrojenie | F14: 1 | G14: Mele | H14: X | I14: X | J14: 1 | K14: Sojusznka/Wro | L14: Zniwecz jedną akcje przeciniwka || Rozbrój wroga (save: d20+dex>d20+dex wroga) | O14: Kusza ręczna | Z14: Karty Broń 2
B15: Buzdygan | C15: 0 | D15: =COUNT(C15:C17) -> 3 | E15: Cios | F15: 1 | G15: Mele | H15: d20-2+dex | I15: 2xstr | J15: 1 | K15: Gracza | L15: Advantage na kolejny atak przeciwko trafionemu przeciwnikowi o mniejszym str od ciebie | M15: 5 | O15: Kusza ciężka | Z15: Karta 1 | AB15: Użyta | AC15: =Ekwipunek!O32 -> FALSE | AD15: Karta 2 | AF15: Użyta | AG15: =Ekwipunek!S32 -> FALSE | AH15: Karta 3 | AJ15: Użyta | AK15: =Ekwipunek!W32 -> FALSE | AL15: Karta 4 | AN15: Użyta | AO15: =Ekwipunek!AA32 -> FALSE
C16: 5 | E16: Obuch | F16: 1 | G16: Mele | H16: d20-4+dex | I16: 3xstr | J16: 1 | K16: Gracza | L16: Odbierz turę przeciwnikowi o str mniejszym od ciebie | O16: Łuk krótki | Q16: Broń 2 | Z16: Wyrzucona kostka | AB16: =Ekwipunek!N33 -> 0 | AD16: Wyrzucona kostka | AF16: =Ekwipunek!R33 -> 0 | AH16: Wyrzucona kostka | AJ16: =Ekwipunek!V33 -> 0 | AL16: Wyrzucona kostka | AN16: =Ekwipunek!Z33 -> 0
C17: 10 | E17: Łamacz | F17: 1 | G17: Mele | H17: d20-6+dex | I17: 4xstr | J17: 1 | K17: Gracza | L17: Advantage na wszystkie ataki przeciwko trafionemu przeciwnikowi o mniejszym str od ciebie || Jeżeli nie trafisz, przeciwnik zostaje trafiony "Ciosem" | O17: Łuk długi | Q17: kostki | R17: liczba | U17: akcje | V17: czy użyta? | Z17: {=INDEX($B$3:$M$94,MATCH(Ekwipunek!$H$9,Obl!$B$3:$B$94,0)+_xlfn.XLOOKUP(AB$16,Obl!$Q$18:$Q$24,Obl!$R$18:$R$24,,-1),4)} -> Prosty | AD17: {=INDEX($B$3:$M$94,MATCH(Ekwipunek!$H$9,Obl!$B$3:$B$94,0)+_xlfn.XLOOKUP(AF$16,Obl!$Q$18:$Q$24,Obl!$R$18:$R$24,,-1),4)} -> Prosty | AH17: {=INDEX($B$3:$M$94,MATCH(Ekwipunek!$H$9,Obl!$B$3:$B$94,0)+_xlfn.XLOOKUP(AJ$16,Obl!$Q$18:$Q$24,Obl!$R$18:$R$24,,-1),4)} -> Prosty | AL17: {=INDEX($B$3:$M$94,MATCH(Ekwipunek!$H$9,Obl!$B$3:$B$94,0)+_xlfn.XLOOKUP(AN$16,Obl!$Q$18:$Q$24,Obl!$R$18:$R$24,,-1),4)} -> Prosty
B18: Włócznia | C18: 0 | D18: =COUNT(C18:C20) -> 3 | E18: Pchnięcia | F18: 2 | G18: 5ft | H18: d20+dex | I18: d4+str | J18: 3 | K18: Gracza/Wroga | L18: W trakcie swojej tury możesz wykonac tylko jeden atak || Możesz wykonać tylko jeden atak na przeciwnika pozostajacego w twojej strefie kontrolii || Odpychasz wroga o 5ft (d20+str>13+str) | M18: 5 | O18: Samopał | Q18: {=OFFSET(_xlfn.XLOOKUP(Ekwipunek!H9,Obl!$B$3:$B$94,Obl!$C$3:$C$94),0,0,_xlfn.XLOOKUP(Ekwipunek!H9,Obl!$B$3:$B$94,$D$3:$D$94))} -> 0 | R18: 0 | T18: karta 1 | U18: =Ekwipunek!O39 -> 0.5 | V18: =Ekwipunek!O32 -> FALSE | W18: =IF(V18=TRUE,U18,0) -> 0 | Z18: {=INDEX($B$3:$M$94,MATCH(Ekwipunek!$H$9,Obl!$B$3:$B$94,0)+_xlfn.XLOOKUP(AB$16,Obl!$Q$3:$Q$10,Obl!$R$3:$R$10,,-1),11)} -> Zwykły, chamski atak | AD18: {=INDEX($B$3:$M$94,MATCH(Ekwipunek!$H$9,Obl!$B$3:$B$94,0)+_xlfn.XLOOKUP(AF$16,Obl!$Q$3:$Q$10,Obl!$R$3:$R$10,,-1),11)} -> Zwykły, chamski atak | AH18: {=INDEX($B$3:$M$94,MATCH(Ekwipunek!$H$9,Obl!$B$3:$B$94,0)+_xlfn.XLOOKUP(AJ$16,Obl!$Q$3:$Q$10,Obl!$R$3:$R$10,,-1),11)} -> Zwykły, chamski atak | AL18: {=INDEX($B$3:$M$94,MATCH(Ekwipunek!$H$9,Obl!$B$3:$B$94,0)+_xlfn.XLOOKUP(AN$16,Obl!$Q$3:$Q$10,Obl!$R$3:$R$10,,-1),11)} -> Zwykły, chamski atak
C19: 5 | E19: Ściana włóczni | F19: 1 | G19: 5ft | H19: d20+dex | I19: d4+str | J19: 3 | K19: Sojusznika | L19: Aktywój "Pchnięcia" po tym jak twój sojusznik aktywóje "Pchnięcia" | O19: Muszkiet | Q19: 3 | R19: 1 | T19: karta 2 | U19: =Ekwipunek!S39 | V19: =Ekwipunek!S32 -> FALSE | W19: =IF(V19=TRUE,U19,0) -> 0
C20: 10 | E20: Przygotowanie | F20: 0 | K20: Gracza | L20: Wszystkie pchnięcia do końca następnej tury zadają d4+2xstr | O20: Oszczep | Q20: 8 | R20: 2 | T20: karta 3 | U20: =Ekwipunek!W39 | V20: =Ekwipunek!W32 -> FALSE | W20: =IF(V20=TRUE,U20,0) -> 0
B21: Miecz długi | C21: 0 | D21: =COUNT(C21:C23) -> 3 | E21: Cięcie | F21: 1 | G21: Mele | H21: d20+dex | I21: d6+dex+str | J21: 1 | K21: Gracza | L21: Nie możesz używać innej broni jednoręcznej||zadaje 50% dmg potworą (jeśli rzut ponirzej 16) | M21: 25 | O21: Toporek do rzucania | Q21: 10 | R21: 3 | T21: karta 4 | U21: =Ekwipunek!AA39 | V21: =Ekwipunek!AA32 -> FALSE | W21: =IF(V21=TRUE,U21,0) -> 0
C22: 5 | E22: Kontry | F22: 1 | G22: Mele | K22: Wroga | L22: Gdy przeciwnik nie trafi ataku wymierzonego w ciebie lub gdy zablokujesz atak przeciwnika, użyj "Cięcia" na przeciwniku | O22: Noże do rzucania | R22: 4 | Z22: Dmg | AA22: {=INDEX($B$3:$M$94,MATCH(Ekwipunek!$H$9,Obl!$B$3:$B$94,0)+_xlfn.XLOOKUP(AB$16,Obl!$Q$18:$Q$24,Obl!$R$18:$R$24,,-1),8)} -> str | AB22: Akcja | AC22: {=INDEX($B$3:$M$94,MATCH(Ekwipunek!$H$9,Obl!$B$3:$B$94,0)+_xlfn.XLOOKUP(AB$16,Obl!$Q$18:$Q$24,Obl!$R$18:$R$24,,-1),5)} -> 0.5 | AD22: Dmg | AE22: {=INDEX($B$3:$M$94,MATCH(Ekwipunek!$H$9,Obl!$B$3:$B$94,0)+_xlfn.XLOOKUP(AF$16,Obl!$Q$18:$Q$24,Obl!$R$18:$R$24,,-1),8)} -> str | AF22: Akcja | AG22: {=INDEX($B$3:$M$94,MATCH(Ekwipunek!$H$9,Obl!$B$3:$B$94,0)+_xlfn.XLOOKUP(AF$16,Obl!$Q$18:$Q$24,Obl!$R$18:$R$24,,-1),5)} -> 0.5 | AH22: Dmg | AI22: {=INDEX($B$3:$M$94,MATCH(Ekwipunek!$H$9,Obl!$B$3:$B$94,0)+_xlfn.XLOOKUP(AJ$16,Obl!$Q$18:$Q$24,Obl!$R$18:$R$24,,-1),8)} -> str | AJ22: Akcja | AK22: {=INDEX($B$3:$M$94,MATCH(Ekwipunek!$H$9,Obl!$B$3:$B$94,0)+_xlfn.XLOOKUP(AJ$16,Obl!$Q$18:$Q$24,Obl!$R$18:$R$24,,-1),5)} -> 0.5 | AL22: Dmg | AM22: {=INDEX($B$3:$M$94,MATCH(Ekwipunek!$H$9,Obl!$B$3:$B$94,0)+_xlfn.XLOOKUP(AN$16,Obl!$Q$18:$Q$24,Obl!$R$18:$R$24,,-1),8)} -> str | AN22: Akcja | AO22: {=INDEX($B$3:$M$94,MATCH(Ekwipunek!$H$9,Obl!$B$3:$B$94,0)+_xlfn.XLOOKUP(AN$16,Obl!$Q$18:$Q$24,Obl!$R$18:$R$24,,-1),5)} -> 0.5
C23: 10 | E23: Ścięcie | F23: 1 | G23: Mele | H23: d20+dex | I23: 2d6+dex+str | J23: 1 | K23: Gracza | L23: Rzuć d4, w przypadku, gdy wyrzucisz 4, zabij przeciwnika swojego rozmiaru lub zadaj 3xdmg przeciwnikowi większemu od siebie | O23: Tarcza okrągła (drewniana) | R23: 5 | Z23: Trafienie | AA23: {=INDEX($B$3:$M$94,MATCH(Ekwipunek!$H$9,Obl!$B$3:$B$94,0)+_xlfn.XLOOKUP(AB$16,Obl!$Q$18:$Q$24,Obl!$R$18:$R$24,,-1),7)} -> d20+dex | AB23: Ilośc celów | AC23: {=INDEX($B$3:$M$94,MATCH(Ekwipunek!$H$9,Obl!$B$3:$B$94,0)+_xlfn.XLOOKUP(AB$16,Obl!$Q$18:$Q$24,Obl!$R$18:$R$24,,-1),9)} -> 1 | AD23: Trafienie | AE23: {=INDEX($B$3:$M$94,MATCH(Ekwipunek!$H$9,Obl!$B$3:$B$94,0)+_xlfn.XLOOKUP(AF$16,Obl!$Q$18:$Q$24,Obl!$R$18:$R$24,,-1),7)} -> d20+dex | AF23: Ilośc celów | AG23: {=INDEX($B$3:$M$94,MATCH(Ekwipunek!$H$9,Obl!$B$3:$B$94,0)+_xlfn.XLOOKUP(AF$16,Obl!$Q$18:$Q$24,Obl!$R$18:$R$24,,-1),9)} -> 1 | AH23: Trafienie | AI23: {=INDEX($B$3:$M$94,MATCH(Ekwipunek!$H$9,Obl!$B$3:$B$94,0)+_xlfn.XLOOKUP(AJ$16,Obl!$Q$18:$Q$24,Obl!$R$18:$R$24,,-1),7)} -> d20+dex | AJ23: Ilośc celów | AK23: {=INDEX($B$3:$M$94,MATCH(Ekwipunek!$H$9,Obl!$B$3:$B$94,0)+_xlfn.XLOOKUP(AJ$16,Obl!$Q$18:$Q$24,Obl!$R$18:$R$24,,-1),9)} -> 1 | AL23: Trafienie | AM23: {=INDEX($B$3:$M$94,MATCH(Ekwipunek!$H$9,Obl!$B$3:$B$94,0)+_xlfn.XLOOKUP(AN$16,Obl!$Q$18:$Q$24,Obl!$R$18:$R$24,,-1),7)} -> d20+dex | AN23: Ilośc celów | AO23: {=INDEX($B$3:$M$94,MATCH(Ekwipunek!$H$9,Obl!$B$3:$B$94,0)+_xlfn.XLOOKUP(AN$16,Obl!$Q$18:$Q$24,Obl!$R$18:$R$24,,-1),9)} -> 1
B24: Topór dwuręczny | C24: 0 | D24: =COUNT(C24:C26) -> 3 | E24: Ścięcie | F24: 2 | G24: Mele | H24: d20+dex | I24: d12+2xstr | J24: 1 | K24: Gracza | L24: Jeżeli po tym gdy zadasz obrażenia przeciwnikowi, gdy zostanie mu mniej niż 8 życia, ten zostaje zabity || Niszczysz drewnianą tarczę wroga || Dezaktywujesz do końca tury inne tarcz | M24: 45 | O24: Tarcza migdałowata (drewniana) | R24: 6 | Z24: Zasięg | AA24: {=INDEX($B$3:$M$94,MATCH(Ekwipunek!$H$9,Obl!$B$3:$B$94,0)+_xlfn.XLOOKUP(AB$16,Obl!$Q$18:$Q$24,Obl!$R$18:$R$24,,-1),6)} -> Mele | AB24: Tura | AC24: {=INDEX($B$3:$M$94,MATCH(Ekwipunek!$H$9,Obl!$B$3:$B$94,0)+_xlfn.XLOOKUP(AB$16,Obl!$Q$18:$Q$24,Obl!$R$18:$R$24,,-1),10)} -> Gracza | AD24: Zasięg | AE24: {=INDEX($B$3:$M$94,MATCH(Ekwipunek!$H$9,Obl!$B$3:$B$94,0)+_xlfn.XLOOKUP(AF$16,Obl!$Q$18:$Q$24,Obl!$R$18:$R$24,,-1),6)} -> Mele | AF24: Tura | AG24: {=INDEX($B$3:$M$94,MATCH(Ekwipunek!$H$9,Obl!$B$3:$B$94,0)+_xlfn.XLOOKUP(AF$16,Obl!$Q$18:$Q$24,Obl!$R$18:$R$24,,-1),10)} -> Gracza | AH24: Zasięg | AI24: {=INDEX($B$3:$M$94,MATCH(Ekwipunek!$H$9,Obl!$B$3:$B$94,0)+_xlfn.XLOOKUP(AJ$16,Obl!$Q$18:$Q$24,Obl!$R$18:$R$24,,-1),6)} -> Mele | AJ24: Tura | AK24: {=INDEX($B$3:$M$94,MATCH(Ekwipunek!$H$9,Obl!$B$3:$B$94,0)+_xlfn.XLOOKUP(AJ$16,Obl!$Q$18:$Q$24,Obl!$R$18:$R$24,,-1),10)} -> Gracza | AL24: Zasięg | AM24: {=INDEX($B$3:$M$94,MATCH(Ekwipunek!$H$9,Obl!$B$3:$B$94,0)+_xlfn.XLOOKUP(AN$16,Obl!$Q$18:$Q$24,Obl!$R$18:$R$24,,-1),6)} -> Mele | AN24: Tura | AO24: {=INDEX($B$3:$M$94,MATCH(Ekwipunek!$H$9,Obl!$B$3:$B$94,0)+_xlfn.XLOOKUP(AN$16,Obl!$Q$18:$Q$24,Obl!$R$18:$R$24,,-1),10)} -> Gracza
C25: 5 | E25: Siekacz | F25: 3 | G25: Mele | H25: d12+2xdex | I25: d6+2str | J25: sąsiedzi | K25: Gracza | L25: Jeżeli po tym gdy zadasz obrażenia przeciwnikowi, gdy zostanie mu mniej niż 6 życia, ten zostanie zabity | O25: Puklerz (drewniany)
C26: 10 | E26: Gilotyna | F26: 2 | G26: 5ft | H26: d20+dex | I26: d12+2xstr | J26: 1 | K26: Gracza | L26: Ataku nie można zablokować || Jeżeli po tym gdy zadasz obrażenia przeciwnikowi, gdy zostanie mu mniej niż 20 życia, ten zostaje zabity | O26: Tarcza rzymska (drewniana)
B27: Miecz dwuręczny | C27: 0 | D27: =COUNT(C27:C30) -> 4 | E27: Pchnięcie | F27: 2 | G27: Mele | H27: d20+dex | I27: 2d6+(dex+str) | J27: 3 w rzędzie | K27: Gracza | L27: Potężny atak na wprost | M27: 60 | O27: Tarcza okrągła (żelazna)
C28: 1 | E28: Cięcie z zamachu | F28: 2 | G28: Mele/5ft | H28: d20+dex | I28: 2d6+(dex+str) | J28: 3 w łuku | K28: Gracza | L28: Potężny atak w łuku | O28: Tarcza migdałowata (żelazna)
C29: 2 | E29: Bloki | F29: 1 | G29: Mele/5ft | J29: 3 | K29: Wroga | L29: Zniwecz jedną akcję sonsiadującego przeciwnika (save: d20+2xdex>rzut na trafienie wroga) || Możliwe 3 użycia | O29: Puklerz (żelazny)
C30: 10 | E30: Przygotowanie | F30: 1 | K30: Sojusznika/Wro | L30: Użyj dowolną kartę miecza dwóręcznego | O30: Tarcza rzymska (żelazna)
B31: Młot dwuręczny | C31: 0 | D31: =COUNT(C31:C33) -> 3 | E31: Uderzenie | F31: 2 | G31: 5ft | H31: d20+1/2dex | I31: d12+2xstr | J31: 1 | K31: Gracza | L31: Przeciwnik zostaje przesunięty na koniec turn ordera (save: d20+str>15+2xstr) | M31: 30
C32: 6 | E32: Trzęsienei ziemi | F32: 3 | G32: 5ft | H32: d20 | I32: d12+2xstr | J32: 1 | K32: Gracz | L32: Zniwecz akcję istot sonsiadujących z polem ataku (save: d20+str>15+2xstr) || Istoty na sonsiadujących polach otrzymuja d4+str dmg
C33: 10 | E33: Miażdżący cios | F33: 2 | G33: mele | H33: d20 | I33: 2d12+4xstr | J33: 1 | K33: Gracz | L33: Spraw, że sąsiedzi przeciwnika mogą go raz zaatakować za darmo (save: d20+str>15+2xstr)
B34: Włócznia długa | C34: 0 | D34: =COUNT(C34:C36) -> 3 | E34: Pchnięcia | F34: 2 | G34: 10ft | H34: d20+dex | I34: d8+2xstr | J34: 3 | K34: Gracza/Wroga | L34: W trakcie swojej tury możesz wykonac tylko jeden atak || Możesz wykonać tylko jeden atak na przeciwnika pozostajacego w twojej strefie kontrolii || Odpychasz wroga o 5ft (d20+str>13+str) | M34: 20
C35: 5 | E35: Ściana włóczni | F35: 1 | G35: 10ft | H35: d20+dex | I35: d8+2xstr | J35: 3 | K35: Sojusznika | L35: Aktywój "Pchnięcia" po tym jak twój sojusznik aktywóje "Pchnięcia"
C36: 10 | E36: Przygotowanie | F36: 0 | K36: Gracza | L36: Wszystkie pchnięcia do końca następnej tury zadają d8+3xstr
B37: Morning star dwuręczny | C37: 0 | D37: =COUNT(C37:C40) -> 4 | E37: Zamachy | F37: 1 | G37: 5ft | H37: d20+dex | I37: d8+1,5str | J37: 2 | K37: Gracza | L37: Odpycha 5ft || Możesz przerzucić 2 kostki w trakcie używania tej karty | M37: 25
C38: 3 | E38: Złapanie | F38: 1 | G38: 10ft | H38: d20+dex | I38: d6+str | J38: 1 | K38: Gracza | L38: Przewracasz i przeciągasz istotę 10ft w wybranym kierunku nie oddalając jej od siebie (save: d20+str>16+2str)
C39: 6 | E39: Szybkie uderzenia | F39: 1.5 | G39: 5ft | H39: d20+dex | I39: d8+1,5str | J39: 3 | K39: Gracza | L39: Możesz przerzucić 6 kostek w trakcie użwania tej karty
C40: 10 | E40: Złapanie | F40: 1.5 | G40: 5ft | H40: d20+dex | I40: d8+1,5str | J40: 6 | K40: Sojusznika | L40: Gdy sojusznik zaatakuje przeciwnika, możesz wykonać "Zamachy" || Sojusznik otrzymuje możliwość przerzucenia jednej ze swoich kostek w trakcie ataku
...
